<?xml version="1.0" ?>
<sdf version="1.9">
  <model name="tugbot">
    <static>false</static>

    <!-- Base link with lidar -->
    <link name="base_link">
      <pose>0 0 0.1 0 0 0</pose>

      <visual name="visual">
        <geometry>
          <cylinder>
            <radius>0.2</radius>
            <length>0.1</length>
          </cylinder>
        </geometry>
      </visual>

      <collision name="collision">
        <geometry>
          <cylinder>
            <radius>0.2</radius>
            <length>0.1</length>
          </cylinder>
        </geometry>
      </collision>

      <!-- ✅ 2D Lidar Sensor -->
      <sensor name="lidar" type="gpu_lidar">
        <pose>0 0 0.25 0 0 0</pose>
        <update_rate>15</update_rate>
        <ray>
          <scan>
            <horizontal>
              <samples>720</samples>
              <resolution>1</resolution>
              <min_angle>-1.5708</min_angle>
              <max_angle>1.5708</max_angle>
            </horizontal>
          </scan>
          <range>
            <min>0.12</min>
            <max>10.0</max>
            <resolution>0.01</resolution>
          </range>
        </ray>
        <plugin name="ros2_laser_bridge" filename="gz-ros2-laser-scan-system">
          <topic>/scan</topic>
          <frame_id>base_link</frame_id>
        </plugin>
      </sensor>
    </link>

    <!-- Left wheel -->
    <link name="left_wheel">
      <pose>-0.1 0.25 0.05 0 0 0</pose>
      <visual name="visual">
        <geometry>
          <cylinder>
            <radius>0.05</radius>
            <length>0.05</length>
          </cylinder>
        </geometry>
      </visual>
      <collision name="collision">
        <geometry>
          <cylinder>
            <radius>0.05</radius>
            <length>0.05</length>
          </cylinder>
        </geometry>
      </collision>
    </link>

    <!-- Right wheel -->
    <link name="right_wheel">
      <pose>0.1 -0.25 0.05 0 0 0</pose>
      <visual name="visual">
        <geometry>
          <cylinder>
            <radius>0.05</radius>
            <length>0.05</length>
          </cylinder>
        </geometry>
      </visual>
      <collision name="collision">
        <geometry>
          <cylinder>
            <radius>0.05</radius>
            <length>0.05</length>
          </cylinder>
        </geometry>
      </collision>
    </link>
    <!-- Lidar Link -->
    <link name="lidar_link">
    <pose>0 0 0.25 0 0 0</pose>
    <sensor name="scan" type="gpu_lidar">
        <pose>0 0 0 0 0 0</pose>
        <update_rate>15</update_rate>
        <ray>
        <scan>
            <horizontal>
            <samples>720</samples>
            <resolution>1</resolution>
            <min_angle>-1.5708</min_angle>
            <max_angle>1.5708</max_angle>
            </horizontal>
        </scan>
        <range>
            <min>0.12</min>
            <max>10.0</max>
            <resolution>0.01</resolution>
        </range>
        </ray>
        <plugin name="ros2_laser_bridge" filename="gz-ros2-laser-scan-system">
        <topic>/scan</topic>
        <frame_id>lidar_link</frame_id>
        </plugin>
    </sensor>
    </link>


    <!-- Joints -->
    <joint name="left_wheel_joint" type="continuous">
      <parent>base_link</parent>
      <child>left_wheel</child>
      <axis>
        <xyz>0 1 0</xyz>
      </axis>
    </joint>

    <joint name="right_wheel_joint" type="continuous">
      <parent>base_link</parent>
      <child>right_wheel</child>
      <axis>
        <xyz>0 1 0</xyz>
      </axis>
    </joint>
    <joint name="lidar_joint" type="fixed">
        <parent>base_link</parent>
        <child>lidar_link</child>
    </joint>


    <!-- Diff Drive Plugin -->
    <plugin name="diff_drive" filename="gz-sim-diff-drive-system">
      <left_joint>left_wheel_joint</left_joint>
      <right_joint>right_wheel_joint</right_joint>
      <wheel_separation>0.5</wheel_separation>
      <wheel_radius>0.05</wheel_radius>
      <topic>/model/tugbot/cmd_vel</topic>
      <odom_topic>/model/tugbot/odometry</odom_topic>
      <publish_odom>true</publish_odom>
      <publish_tf>true</publish_tf>
      <odometry_source>world</odometry_source>
      <frame_id>base_link</frame_id>
      <odom_frame_id>odom</odom_frame_id>
    </plugin>
  </model>
</sdf>
